<include xmlns:xacro="http://www.ros.org/wiki/xacro">
<gazebo>

<link name='right_diff_rail'>
    <inertial>
    <mass>0.000236124</mass>
    <inertia>
        <ixx>3.68579e-08</ixx>
        <ixy>0</ixy>
        <ixz>0</ixz>
        <iyy>1.28668e-06</iyy>
        <iyz>0</iyz>
        <izz>1.28951e-06</izz>
    </inertia>
    <pose>0 0 0 0 -0 0</pose>
    </inertial>
    <pose>-0.116498 -0.287057 0.138334 0 -0 0</pose>
    <xacro:link_defaults/>
    <visual name='visual'>
    <pose>0 0 0 0 -0 0</pose>
    <geometry>
        <box>
        <size>0.225 0.01 0.01</size>
        </box>
    </geometry>
    <material>
        <lighting>1</lighting>
        <script>
        <uri>file://media/materials/scripts/gazebo.material</uri>
        <name>Gazebo/Grey</name>
        </script>
        <shader type='pixel'/>
        <emissive>0 0 0 1</emissive>
    </material>
    <xacro:visual_defaults/>
    </visual>
</link>
<link name='left_diff_rail'>
    <inertial>
    <mass>0.000236124</mass>
    <inertia>
        <ixx>3.68579e-08</ixx>
        <ixy>0</ixy>
        <ixz>0</ixz>
        <iyy>1.28668e-06</iyy>
        <iyz>0</iyz>
        <izz>1.28951e-06</izz>
    </inertia>
    <pose>0 0 0 0 -0 0</pose>
    </inertial>
    <pose>-0.108281 0.282192 0.138334 0 -0 0</pose>
    <xacro:link_defaults/>
    <visual name='visual'>
    <pose>0 0 0 0 -0 0</pose>
    <geometry>
        <box>
        <size>0.225 0.01 0.01</size>
        </box>
    </geometry>
    <material>
        <lighting>1</lighting>
        <script>
        <uri>file://media/materials/scripts/gazebo.material</uri>
        <name>Gazebo/Grey</name>
        </script>
        <shader type='pixel'/>
        <emissive>0 0 0 1</emissive>
    </material>
    <xacro:visual_defaults/>
    </visual>
</link>
<joint name='right_diff_rail_to_diff' type='fixed'>  # TODO: or revolute/revolute2/ball ?
    <parent>right_diff_rail</parent>
    <child>differential</child>
    <pose>0 0 0.25 0 -0 0</pose>
    <axis>
    <xyz>0 0 1</xyz>
    <limit>
        <lower>-1e+16</lower>
        <upper>1e+16</upper>
        <effort>-1</effort>
        <velocity>-1</velocity>
    </limit>
    <dynamics>
        <spring_reference>0</spring_reference>
        <spring_stiffness>0</spring_stiffness>
        <damping>0</damping>
        <friction>0</friction>
    </dynamics>
    </axis>
    <physics>
    <ode>
        <limit>
        <cfm>0</cfm>
        <erp>0.2</erp>
        </limit>
        <suspension>
        <cfm>0</cfm>
        <erp>0.2</erp>
        </suspension>
    </ode>
    </physics>
</joint>
<joint name='right_diff_rail_to_handle' type='revolute'>
    <parent>right_diff_rail</parent>
    <child>right_handle</child>
    <pose>0 0.15 0 0 -0 0</pose>
    <axis>
    <xyz>0 0 1</xyz>
    <limit>
        <lower>-1e+16</lower>
        <upper>1e+16</upper>
        <effort>-1</effort>
        <velocity>-1</velocity>
    </limit>
    <dynamics>
        <spring_reference>0</spring_reference>
        <spring_stiffness>0</spring_stiffness>
        <damping>0</damping>
        <friction>0</friction>
    </dynamics>
    </axis>
    <physics>
    <ode>
        <limit>
        <cfm>0</cfm>
        <erp>0.2</erp>
        </limit>
        <suspension>
        <cfm>0</cfm>
        <erp>0.2</erp>
        </suspension>
    </ode>
    </physics>
</joint>
<joint name='left_diff_rail_to_handle' type='revolute'>
    <parent>left_diff_rail</parent>
    <child>left_handle</child>
    <pose>0 0.15 0 0 -0 0</pose>
    <axis>
    <xyz>0 0 1</xyz>
    <limit>
        <lower>-1e+16</lower>
        <upper>1e+16</upper>
        <effort>-1</effort>
        <velocity>-1</velocity>
    </limit>
    <dynamics>
        <spring_reference>0</spring_reference>
        <spring_stiffness>0</spring_stiffness>
        <damping>0</damping>
        <friction>0</friction>
    </dynamics>
    </axis>
    <physics>
    <ode>
        <limit>
        <cfm>0</cfm>
        <erp>0.2</erp>
        </limit>
        <suspension>
        <cfm>0</cfm>
        <erp>0.2</erp>
        </suspension>
    </ode>
    </physics>
</joint>
<joint name='left_diff_rail_to_diff' type='fixed'> # TODO: or revolute/revolute2/ball ?
    <parent>left_diff_rail</parent>
    <child>differential</child>
    <pose>0 0 -0.25 0 -0 0</pose>
    <axis>
    <xyz>0 0 1</xyz>
    <limit>
        <lower>-1e+16</lower>
        <upper>1e+16</upper>
        <effort>-1</effort>
        <velocity>-1</velocity>
    </limit>
    <dynamics>
        <spring_reference>0</spring_reference>
        <spring_stiffness>0</spring_stiffness>
        <damping>0</damping>
        <friction>0</friction>
    </dynamics>
    </axis>
    <physics>
    <ode>
        <limit>
        <cfm>0</cfm>
        <erp>0.2</erp>
        </limit>
        <suspension>
        <cfm>0</cfm>
        <erp>0.2</erp>
        </suspension>
    </ode>
    </physics>
</joint>

</gazebo>
</include>
