<?xml version="1.0" ?>
<!-- =================================================================================== -->
<!-- |    This document was autogenerated by xacro from /home/igor/Baseplate/models/rover/model.xacro | -->
<!-- |    EDITING THIS FILE BY HAND IS NOT RECOMMENDED                                 | -->
<!-- =================================================================================== -->
<robot name="rover">
  <gazebo>
    <plugin filename="libgazebo_ros_control.so" name="gazebo_ros_control">
      <robotNamespace>/rover</robotNamespace>
    </plugin>
  </gazebo>
  <static>0</static>
  <allow_auto_disable>1</allow_auto_disable>
  <link name="base_link">
    <gravity>1</gravity>
    <self_collide>0</self_collide>
    <kinematic>0</kinematic>
    <enable_wind>0</enable_wind>
    <visual name="visual">
      <origin rpy="1.5707 0 0" xyz="0 0 0"/>
      <geometry>
        <mesh filename="file:///opt/rover/meshes/rover/joint1_box.stl" scale="1 1 1"/>
      </geometry>
      <transparency>0</transparency>
      <cast_shadows>1</cast_shadows>
    </visual>
    <collision name="chassis_collision">
      <origin rpy="0 0 0" xyz="-0.07 0 -0.02"/>
      <laser_retro>0</laser_retro>
      <max_contacts>10</max_contacts>
      <geometry>
        <box size="0.686 0.466 0.2264"/>
      </geometry>
    </collision>
  </link>
  <link name="chassis_inertial">
    <gravity>1</gravity>
    <inertial>
      <inertia ixx="0.242" ixy="-0.002" ixz="0" iyy="0.49" iyz="0" izz="0.348"/>
      <mass value="20"/>
    </inertial>
  </link>
  <joint name="chassis_inertial_fix" type="fixed">
    <parent link="base_link"/>
    <child link="chassis_inertial"/>
  </joint>
  <link name="left_handle">
    <origin rpy="0 0 0" xyz="0 0.290 0"/>
    <inertial>
      <mass value="2.209"/>
      <inertia ixx="0.031" ixy="0.027" ixz="-0.001" iyy="0.073" iyz="-0.002" izz="0.099"/>
    </inertial>
    <visual name="visual">
      <origin rpy="0 0 0" xyz="0 0 0"/>
      <geometry>
        <mesh filename="file:///opt/rover/meshes/rover/joint2L.stl" scale="1 1 1"/>
      </geometry>
      <transparency>0</transparency>
      <cast_shadows>1</cast_shadows>
    </visual>
    <gravity>1</gravity>
    <self_collide>0</self_collide>
    <kinematic>0</kinematic>
    <enable_wind>0</enable_wind>
  </link>
  <joint name="left_handle_joint" type="revolute">
    <parent link="base_link"/>
    <child link="left_handle"/>
    <axis xyz="0 0 1"/>
    <origin rpy="1.5707 0 0" xyz="0 0.290 0"/>
    <limit effort="1000.0" lower="-0.524" upper="0.524" velocity="1.5707"/>
  </joint>
  <link name="right_handle">
    <origin rpy="0 0 0" xyz="0 -0.290 0"/>
    <inertial>
      <mass value="2.209"/>
      <inertia ixx="0.031" ixy="0.027" ixz="-0.001" iyy="0.073" iyz="0.002" izz="0.099"/>
    </inertial>
    <visual name="visual">
      <origin rpy="0 0 0" xyz="0 0 0"/>
      <geometry>
        <mesh filename="file:///opt/rover/meshes/rover/joint2R.stl" scale="1 1 1"/>
      </geometry>
      <transparency>0</transparency>
      <cast_shadows>1</cast_shadows>
    </visual>
    <gravity>1</gravity>
    <self_collide>0</self_collide>
    <kinematic>0</kinematic>
    <enable_wind>0</enable_wind>
  </link>
  <joint name="right_handle_joint" type="revolute">
    <parent link="base_link"/>
    <child link="right_handle"/>
    <axis xyz="0 0 1"/>
    <origin rpy="1.5707 0 0" xyz="0 -0.290 0"/>
    <limit effort="1000.0" lower="-0.524" upper="0.524" velocity="1.5707"/>
  </joint>
  <link name="right_boggie">
    <origin rpy="0 0 0" xyz="0 0 0"/>
    <inertial>
      <mass value="1.699"/>
      <inertia ixx="0.024" ixy="0" ixz="0" iyy="0.32" iyz="0.004" izz="0.05"/>
    </inertial>
    <visual name="visual">
      <origin rpy="0 0 0" xyz="0 0 0"/>
      <geometry>
        <mesh filename="file:///opt/rover/meshes/rover/joint3.stl" scale="1 1 1"/>
      </geometry>
      <transparency>0</transparency>
      <cast_shadows>1</cast_shadows>
    </visual>
    <gravity>1</gravity>
    <self_collide>0</self_collide>
    <kinematic>0</kinematic>
    <enable_wind>0</enable_wind>
  </link>
  <joint name="right_boggie_joint" type="revolute">
    <parent link="right_handle"/>
    <child link="right_boggie"/>
    <axis xyz="0 0 1"/>
    <origin rpy="0 0 0" xyz="-0.239726 -0.07490 -0.006"/>
    <limit effort="1000.0" lower="-0.524" upper="0.524" velocity="1.5707"/>
  </joint>
  <link name="left_boggie">
    <origin rpy="0 0 0" xyz="0 0 0"/>
    <inertial>
      <mass value="1.699"/>
      <inertia ixx="0.024" ixy="0" ixz="0" iyy="0.32" iyz="0.004" izz="0.05"/>
    </inertial>
    <visual name="visual">
      <origin rpy="0 3.14159 0" xyz="0 0 0"/>
      <geometry>
        <mesh filename="file:///opt/rover/meshes/rover/joint3.stl" scale="1 1 1"/>
      </geometry>
      <transparency>0</transparency>
      <cast_shadows>1</cast_shadows>
    </visual>
    <gravity>1</gravity>
    <self_collide>0</self_collide>
    <kinematic>0</kinematic>
    <enable_wind>0</enable_wind>
  </link>
  <joint name="left_boggie_joint" type="revolute">
    <parent link="left_handle"/>
    <child link="left_boggie"/>
    <axis xyz="0 0 1"/>
    <origin rpy="0 0 0" xyz="-0.239726 -0.07490 0.006"/>
    <limit effort="1000.0" lower="-0.524" upper="0.524" velocity="1.5707"/>
  </joint>
  <link name="differential">
    <origin rpy="0 0 0" xyz="0 0 0"/>
    <inertial>
      <mass value="2.7"/>
      <inertia ixx="0.012" ixy="0" ixz="0" iyy="0.012" iyz="0" izz="0"/>
    </inertial>
    <visual name="visual">
      <origin rpy="0 0 0" xyz="0 0 0"/>
      <geometry>
        <mesh filename="file:///opt/rover/meshes/rover/joint4-diff.stl" scale="1 1 1"/>
      </geometry>
      <transparency>0</transparency>
      <cast_shadows>1</cast_shadows>
    </visual>
    <gravity>1</gravity>
    <self_collide>0</self_collide>
    <kinematic>0</kinematic>
    <enable_wind>0</enable_wind>
  </link>
  <joint name="differential_joint" type="continuous">
    <parent link="base_link"/>
    <child link="differential"/>
    <axis xyz="0 1 0"/>
    <origin rpy="1.5707 0 0" xyz="-0.230 0 0.128"/>
  </joint>
  <link name="wheel_1">
    <origin rpy="0 0 0" xyz="0 0 0"/>
    <inertial>
      <mass value="1"/>
      <inertia ixx="0.013" ixy="0" ixz="0" iyy="0.013" iyz="0" izz="0.024"/>
    </inertial>
    <visual name="visual">
      <origin rpy="0 0 0" xyz="0 0 0.034"/>
      <geometry>
        <mesh filename="file:///opt/rover/meshes/rover/wheel.stl" scale="1 1 1"/>
      </geometry>
      <transparency>0</transparency>
      <cast_shadows>1</cast_shadows>
    </visual>
    <collision name="wheel_1_collision">
      <origin rpy="0 0 0" xyz="0 0 0"/>
      <laser_retro>0</laser_retro>
      <max_contacts>10</max_contacts>
      <geometry>
        <cylinder length="0.072" radius="0.128"/>
      </geometry>
    </collision>
    <gravity>1</gravity>
    <self_collide>0</self_collide>
    <kinematic>0</kinematic>
    <enable_wind>0</enable_wind>
  </link>
  <joint name="wheel_1_joint" type="continuous">
    <parent link="right_handle"/>
    <child link="wheel_1"/>
    <axis xyz="0 0 -1"/>
    <origin rpy="0 0 0" xyz="0.264321 -0.213856 0.132"/>
  </joint>
  <link name="wheel_6">
    <origin rpy="0 0 0" xyz="0 0 0"/>
    <inertial>
      <mass value="1"/>
      <inertia ixx="0.013" ixy="0" ixz="0" iyy="0.013" iyz="0" izz="0.024"/>
    </inertial>
    <visual name="visual">
      <origin rpy="0 0 0" xyz="0 0 0.034"/>
      <geometry>
        <mesh filename="file:///opt/rover/meshes/rover/wheel.stl" scale="1 1 1"/>
      </geometry>
      <transparency>0</transparency>
      <cast_shadows>1</cast_shadows>
    </visual>
    <collision name="wheel_6_collision">
      <origin rpy="0 0 0" xyz="0 0 0"/>
      <laser_retro>0</laser_retro>
      <max_contacts>10</max_contacts>
      <geometry>
        <cylinder length="0.072" radius="0.128"/>
      </geometry>
    </collision>
    <gravity>1</gravity>
    <self_collide>0</self_collide>
    <kinematic>0</kinematic>
    <enable_wind>0</enable_wind>
  </link>
  <joint name="wheel_6_joint" type="continuous">
    <parent link="left_handle"/>
    <child link="wheel_6"/>
    <axis xyz="0 0 1"/>
    <origin rpy="3.1414 0 0" xyz="0.264321 -0.213856  -0.132"/>
  </joint>
  <link name="wheel_2">
    <origin rpy="0 0 0" xyz="0 0 0"/>
    <inertial>
      <mass value="1"/>
      <inertia ixx="0.013" ixy="0" ixz="0" iyy="0.013" iyz="0" izz="0.024"/>
    </inertial>
    <visual name="visual">
      <origin rpy="0 0 0" xyz="0 0 0.034"/>
      <geometry>
        <mesh filename="file:///opt/rover/meshes/rover/wheel.stl" scale="1 1 1"/>
      </geometry>
      <transparency>0</transparency>
      <cast_shadows>1</cast_shadows>
    </visual>
    <collision name="wheel_2_collision">
      <origin rpy="0 0 0" xyz="0 0 0"/>
      <laser_retro>0</laser_retro>
      <max_contacts>10</max_contacts>
      <geometry>
        <cylinder length="0.072" radius="0.128"/>
      </geometry>
    </collision>
    <gravity>1</gravity>
    <self_collide>0</self_collide>
    <kinematic>0</kinematic>
    <enable_wind>0</enable_wind>
  </link>
  <joint name="wheel_2_joint" type="continuous">
    <parent link="right_boggie"/>
    <child link="wheel_2"/>
    <axis xyz="0 0 -1"/>
    <origin rpy="0 0 0" xyz="0.167 -0.14  0.138"/>
  </joint>
  <link name="wheel_5">
    <origin rpy="0 0 0" xyz="0 0 0"/>
    <inertial>
      <mass value="1"/>
      <inertia ixx="0.013" ixy="0" ixz="0" iyy="0.013" iyz="0" izz="0.024"/>
    </inertial>
    <visual name="visual">
      <origin rpy="0 0 0" xyz="0 0 0.034"/>
      <geometry>
        <mesh filename="file:///opt/rover/meshes/rover/wheel.stl" scale="1 1 1"/>
      </geometry>
      <transparency>0</transparency>
      <cast_shadows>1</cast_shadows>
    </visual>
    <collision name="wheel_5_collision">
      <origin rpy="0 0 0" xyz="0 0 0"/>
      <laser_retro>0</laser_retro>
      <max_contacts>10</max_contacts>
      <geometry>
        <cylinder length="0.072" radius="0.128"/>
      </geometry>
    </collision>
    <gravity>1</gravity>
    <self_collide>0</self_collide>
    <kinematic>0</kinematic>
    <enable_wind>0</enable_wind>
  </link>
  <joint name="wheel_5_joint" type="continuous">
    <parent link="left_boggie"/>
    <child link="wheel_5"/>
    <axis xyz="0 0 1"/>
    <origin rpy="3.1414 0 0" xyz="0.167 -0.14  -0.138"/>
  </joint>
  <link name="wheel_3">
    <origin rpy="0 0 0" xyz="0 0 0"/>
    <inertial>
      <mass value="1"/>
      <inertia ixx="0.013" ixy="0" ixz="0" iyy="0.013" iyz="0" izz="0.024"/>
    </inertial>
    <visual name="visual">
      <origin rpy="0 0 0" xyz="0 0 0.034"/>
      <geometry>
        <mesh filename="file:///opt/rover/meshes/rover/wheel.stl" scale="1 1 1"/>
      </geometry>
      <transparency>0</transparency>
      <cast_shadows>1</cast_shadows>
    </visual>
    <collision name="wheel_3_collision">
      <origin rpy="0 0 0" xyz="0 0 0"/>
      <laser_retro>0</laser_retro>
      <max_contacts>10</max_contacts>
      <geometry>
        <cylinder length="0.072" radius="0.128"/>
      </geometry>
    </collision>
    <gravity>1</gravity>
    <self_collide>0</self_collide>
    <kinematic>0</kinematic>
    <enable_wind>0</enable_wind>
  </link>
  <joint name="wheel_3_joint" type="continuous">
    <parent link="right_boggie"/>
    <child link="wheel_3"/>
    <axis xyz="0 0 -1"/>
    <origin rpy="0 0 0" xyz="-0.167 -0.14  0.138"/>
  </joint>
  <link name="wheel_4">
    <origin rpy="0 0 0" xyz="0 0 0"/>
    <inertial>
      <mass value="1"/>
      <inertia ixx="0.013" ixy="0" ixz="0" iyy="0.013" iyz="0" izz="0.024"/>
    </inertial>
    <visual name="visual">
      <origin rpy="0 0 0" xyz="0 0 0.034"/>
      <geometry>
        <mesh filename="file:///opt/rover/meshes/rover/wheel.stl" scale="1 1 1"/>
      </geometry>
      <transparency>0</transparency>
      <cast_shadows>1</cast_shadows>
    </visual>
    <collision name="wheel_4_collision">
      <origin rpy="0 0 0" xyz="0 0 0"/>
      <laser_retro>0</laser_retro>
      <max_contacts>10</max_contacts>
      <geometry>
        <cylinder length="0.072" radius="0.128"/>
      </geometry>
    </collision>
    <gravity>1</gravity>
    <self_collide>0</self_collide>
    <kinematic>0</kinematic>
    <enable_wind>0</enable_wind>
  </link>
  <joint name="wheel_4_joint" type="continuous">
    <parent link="left_boggie"/>
    <child link="wheel_4"/>
    <axis xyz="0 0 1"/>
    <origin rpy="3.1414 0 0" xyz="-0.167 -0.14  -0.138"/>
  </joint>
  <gazebo>
    <link name="right_diff_rail">
      <inertial>
        <mass>0.000236124</mass>
        <inertia>
          <ixx>3.68579e-08</ixx>
          <ixy>0</ixy>
          <ixz>0</ixz>
          <iyy>1.28668e-06</iyy>
          <iyz>0</iyz>
          <izz>1.28951e-06</izz>
        </inertia>
        <pose>0 0 0 0 -0 0</pose>
      </inertial>
      <pose>-0.116498 -0.287057 0.138334 0 -0 0</pose>
      <gravity>1</gravity>
      <self_collide>0</self_collide>
      <kinematic>0</kinematic>
      <enable_wind>0</enable_wind>
      <visual name="visual">
        <pose>0 0 0 0 -0 0</pose>
        <geometry>
          <box>
            <size>0.225 0.01 0.01</size>
          </box>
        </geometry>
        <material>
          <lighting>1</lighting>
          <script>
            <uri>file://media/materials/scripts/gazebo.material</uri>
            <name>Gazebo/Grey</name>
          </script>
          <shader type="pixel"/>
          <emissive>0 0 0 1</emissive>
        </material>
        <transparency>0</transparency>
        <cast_shadows>1</cast_shadows>
      </visual>
    </link>
    <link name="left_diff_rail">
      <inertial>
        <mass>0.000236124</mass>
        <inertia>
          <ixx>3.68579e-08</ixx>
          <ixy>0</ixy>
          <ixz>0</ixz>
          <iyy>1.28668e-06</iyy>
          <iyz>0</iyz>
          <izz>1.28951e-06</izz>
        </inertia>
        <pose>0 0 0 0 -0 0</pose>
      </inertial>
      <pose>-0.108281 0.282192 0.138334 0 -0 0</pose>
      <gravity>1</gravity>
      <self_collide>0</self_collide>
      <kinematic>0</kinematic>
      <enable_wind>0</enable_wind>
      <visual name="visual">
        <pose>0 0 0 0 -0 0</pose>
        <geometry>
          <box>
            <size>0.225 0.01 0.01</size>
          </box>
        </geometry>
        <material>
          <lighting>1</lighting>
          <script>
            <uri>file://media/materials/scripts/gazebo.material</uri>
            <name>Gazebo/Grey</name>
          </script>
          <shader type="pixel"/>
          <emissive>0 0 0 1</emissive>
        </material>
        <transparency>0</transparency>
        <cast_shadows>1</cast_shadows>
      </visual>
    </link>
    <joint name="right_diff_rail_to_diff" type="fixed">
        # TODO: or revolute/revolute2/ball ?
    
      <parent>right_diff_rail</parent>
      <child>differential</child>
      <pose>0 0 0.25 0 -0 0</pose>
      <axis>
        <xyz>0 0 1</xyz>
        <limit>
          <lower>-1e+16</lower>
          <upper>1e+16</upper>
          <effort>-1</effort>
          <velocity>-1</velocity>
        </limit>
        <dynamics>
          <spring_reference>0</spring_reference>
          <spring_stiffness>0</spring_stiffness>
          <damping>0</damping>
          <friction>0</friction>
        </dynamics>
      </axis>
      <physics>
        <ode>
          <limit>
            <cfm>0</cfm>
            <erp>0.2</erp>
          </limit>
          <suspension>
            <cfm>0</cfm>
            <erp>0.2</erp>
          </suspension>
        </ode>
      </physics>
    </joint>
    <joint name="right_diff_rail_to_handle" type="revolute">
      <parent>right_diff_rail</parent>
      <child>right_handle</child>
      <pose>0 0.15 0 0 -0 0</pose>
      <axis>
        <xyz>0 0 1</xyz>
        <limit>
          <lower>-1e+16</lower>
          <upper>1e+16</upper>
          <effort>-1</effort>
          <velocity>-1</velocity>
        </limit>
        <dynamics>
          <spring_reference>0</spring_reference>
          <spring_stiffness>0</spring_stiffness>
          <damping>0</damping>
          <friction>0</friction>
        </dynamics>
      </axis>
      <physics>
        <ode>
          <limit>
            <cfm>0</cfm>
            <erp>0.2</erp>
          </limit>
          <suspension>
            <cfm>0</cfm>
            <erp>0.2</erp>
          </suspension>
        </ode>
      </physics>
    </joint>
    <joint name="left_diff_rail_to_handle" type="revolute">
      <parent>left_diff_rail</parent>
      <child>left_handle</child>
      <pose>0 0.15 0 0 -0 0</pose>
      <axis>
        <xyz>0 0 1</xyz>
        <limit>
          <lower>-1e+16</lower>
          <upper>1e+16</upper>
          <effort>-1</effort>
          <velocity>-1</velocity>
        </limit>
        <dynamics>
          <spring_reference>0</spring_reference>
          <spring_stiffness>0</spring_stiffness>
          <damping>0</damping>
          <friction>0</friction>
        </dynamics>
      </axis>
      <physics>
        <ode>
          <limit>
            <cfm>0</cfm>
            <erp>0.2</erp>
          </limit>
          <suspension>
            <cfm>0</cfm>
            <erp>0.2</erp>
          </suspension>
        </ode>
      </physics>
    </joint>
    <joint name="left_diff_rail_to_diff" type="fixed">
       # TODO: or revolute/revolute2/ball ?
    
      <parent>left_diff_rail</parent>
      <child>differential</child>
      <pose>0 0 -0.25 0 -0 0</pose>
      <axis>
        <xyz>0 0 1</xyz>
        <limit>
          <lower>-1e+16</lower>
          <upper>1e+16</upper>
          <effort>-1</effort>
          <velocity>-1</velocity>
        </limit>
        <dynamics>
          <spring_reference>0</spring_reference>
          <spring_stiffness>0</spring_stiffness>
          <damping>0</damping>
          <friction>0</friction>
        </dynamics>
      </axis>
      <physics>
        <ode>
          <limit>
            <cfm>0</cfm>
            <erp>0.2</erp>
          </limit>
          <suspension>
            <cfm>0</cfm>
            <erp>0.2</erp>
          </suspension>
        </ode>
      </physics>
    </joint>
  </gazebo>
  <transmission name="trans_1">
    <type>transmission_interface/SimpleTransmission</type>
    <joint name="wheel_1_joint">
      <hardwareInterface>hardware_interface/VelocityJointInterface</hardwareInterface>
    </joint>
    <actuator name="motor_1">
      <mechanicalReduction>1</mechanicalReduction>
      <hardwareInterface>hardware_interface/VelocityJointInterface</hardwareInterface>
    </actuator>
  </transmission>
  <transmission name="trans_6">
    <type>transmission_interface/SimpleTransmission</type>
    <joint name="wheel_6_joint">
      <hardwareInterface>hardware_interface/VelocityJointInterface</hardwareInterface>
    </joint>
    <actuator name="motor_6">
      <mechanicalReduction>1</mechanicalReduction>
      <hardwareInterface>hardware_interface/VelocityJointInterface</hardwareInterface>
    </actuator>
  </transmission>
  <transmission name="trans_2">
    <type>transmission_interface/SimpleTransmission</type>
    <joint name="wheel_2_joint">
      <hardwareInterface>hardware_interface/VelocityJointInterface</hardwareInterface>
    </joint>
    <actuator name="motor_2">
      <mechanicalReduction>1</mechanicalReduction>
      <hardwareInterface>hardware_interface/VelocityJointInterface</hardwareInterface>
    </actuator>
  </transmission>
  <transmission name="trans_4">
    <type>transmission_interface/SimpleTransmission</type>
    <joint name="wheel_4_joint">
      <hardwareInterface>hardware_interface/VelocityJointInterface</hardwareInterface>
    </joint>
    <actuator name="motor_4">
      <mechanicalReduction>1</mechanicalReduction>
      <hardwareInterface>hardware_interface/VelocityJointInterface</hardwareInterface>
    </actuator>
  </transmission>
  <transmission name="trans_3">
    <type>transmission_interface/SimpleTransmission</type>
    <joint name="wheel_3_joint">
      <hardwareInterface>hardware_interface/VelocityJointInterface</hardwareInterface>
    </joint>
    <actuator name="motor_3">
      <mechanicalReduction>1</mechanicalReduction>
      <hardwareInterface>hardware_interface/VelocityJointInterface</hardwareInterface>
    </actuator>
  </transmission>
  <transmission name="trans_5">
    <type>transmission_interface/SimpleTransmission</type>
    <joint name="wheel_5_joint">
      <hardwareInterface>hardware_interface/VelocityJointInterface</hardwareInterface>
    </joint>
    <actuator name="motor_5">
      <mechanicalReduction>1</mechanicalReduction>
      <hardwareInterface>hardware_interface/VelocityJointInterface</hardwareInterface>
    </actuator>
  </transmission>
</robot>

