<?xml version='1.0'?>
<robot name='rover'>
  <gazebo>
    <plugin name="gazebo_ros_control" filename="libgazebo_ros_control.so">
      <robotNamespace>/rover</robotNamespace>
    </plugin>
  </gazebo>

  <static>0</static>
  <allow_auto_disable>1</allow_auto_disable>

  <link name='chassis'>
    <self_collide>0</self_collide>
    <enable_wind>0</enable_wind>
    <kinematic>0</kinematic>
    <gravity>1</gravity>
    <visual name='visual'>
      <origin xyz="0 0 0" rpy="1.5707 0 0"/>
      <geometry>
        <mesh filename="/opt/rover/meshes/rover/joint1_box.stl" scale="1 1 1" />
      </geometry>
      <transparency>0</transparency>
      <cast_shadows>1</cast_shadows>
    </visual>
    <collision name='chassis_collision'>
      <origin xyz="-0.07 0 -0.02" rpy="0 0 0"/>
      <laser_retro>0</laser_retro>
      <max_contacts>10</max_contacts>
      <geometry>
        <box size="0.686 0.466 0.2264"/>
      </geometry>
    </collision>
  </link>

  <link name="chassis_inertial">
    <gravity>1</gravity>
    <inertial>
        <inertia ixx="0.242"  ixy="-0.002"  ixz="0" iyy="0.49" iyz="0" izz="0.348" />
        <mass value="20"/>
      </inertial>
  </link>
  <joint name='chassis_inertial_fix' type='fixed'>
    <parent link="chassis"/>
    <child link="chassis_inertial"/>
  </joint>

  <link name='left_handle'>
    <origin xyz="0 0.290 0" rpy="0 0 0"/>
    <inertial>
      <mass value="2.209"/>
      <inertia ixx="0.031"  ixy="0.027"  ixz="-0.001" iyy="0.073" iyz="-0.002" izz="0.099" />
    </inertial>
    <visual name='visual'>
      <origin xyz="0 0 0" rpy="0 0 0"/>
      <geometry>
        <mesh filename="/opt/rover/meshes/rover/joint2L.stl" scale="1 1 1" />
      </geometry>
      <transparency>0</transparency>
      <cast_shadows>1</cast_shadows>
    </visual>
    <gravity>1</gravity>
    <self_collide>0</self_collide>
    <kinematic>0</kinematic>
    <enable_wind>0</enable_wind>
  </link>
  <joint name='left_handle_joint' type='continuous'>
    <parent link="chassis"/>
    <child link="left_handle"/>
    <axis xyz="0 0 1"/>
    <origin xyz="0 0.290 0" rpy="1.5707 0 0"/>
  </joint>

  <link name='right_handle'>
    <origin xyz="0 -0.290 0" rpy="0 0 0"/>
    <inertial>
      <mass value="2.209"/>
      <inertia ixx="0.031"  ixy="0.027"  ixz="-0.001" iyy="0.073" iyz="0.002" izz="0.099" />
    </inertial>
    <visual name='visual'>
      <origin xyz="0 0 0" rpy="0 0 0"/>
      <geometry>
        <mesh filename="/opt/rover/meshes/rover/joint2R.stl" scale="1 1 1" />
      </geometry>
      <transparency>0</transparency>
      <cast_shadows>1</cast_shadows>
    </visual>
    <gravity>1</gravity>
    <self_collide>0</self_collide>
    <kinematic>0</kinematic>
    <enable_wind>0</enable_wind>
  </link>
  <joint name='right_handle_joint' type='continuous'>
    <parent link="chassis"/>
    <child link="right_handle"/>
    <axis xyz="0 0 1"/>
    <origin xyz="0 -0.290 0" rpy="1.5707 0 0"/>
  </joint>

  <link name='right_boggie'>
    <origin xyz="0 0 0" rpy="0 0 0"/>
    <inertial>
      <mass value="1.699"/>
      <inertia ixx="0.024"  ixy="0"  ixz="0" iyy="0.32" iyz="0.004" izz="0.05"/>
    </inertial>
    <visual name='visual'>
      <origin xyz="0 0 0" rpy="0 0 0"/>
      <geometry>
        <mesh filename="/opt/rover/meshes/rover/joint3.stl" scale="1 1 1" />
      </geometry>
      <transparency>0</transparency>
      <cast_shadows>1</cast_shadows>
    </visual>
    <gravity>1</gravity>
    <self_collide>0</self_collide>
    <kinematic>0</kinematic>
    <enable_wind>0</enable_wind>
  </link>
  <joint name='right_boggie_joint' type='continuous'>
    <parent link="right_handle"/>
    <child link="right_boggie"/>
    <axis xyz="0 0 1"/>
    <origin xyz="-0.239726 -0.07490 -0.006" rpy="0 0 0"/>
  </joint>

  <link name='left_boggie'>
    <origin xyz="0 0 0" rpy="0 0 0"/>
    <inertial>
      <mass value="1.699"/>
      <inertia ixx="0.024"  ixy="0"  ixz="0" iyy="0.32" iyz="0.004" izz="0.05"/>
    </inertial>
    <visual name='visual'>
      <origin xyz="0 0 0" rpy="0 3.14159 0"/>
      <geometry>
        <mesh filename="/opt/rover/meshes/rover/joint3.stl" scale="1 1 1" />
      </geometry>
      <transparency>0</transparency>
      <cast_shadows>1</cast_shadows>
    </visual>
    <gravity>1</gravity>
    <self_collide>0</self_collide>
    <kinematic>0</kinematic>
    <enable_wind>0</enable_wind>
  </link>
  <joint name='left_boggie_joint' type='continuous'>
    <parent link="left_handle"/>
    <child link="left_boggie"/>
    <axis xyz="0 0 1"/>
    <origin xyz="-0.239726 -0.07490 0.006" rpy="0 0 0"/>
  </joint>

  <link name='differential'>
    <origin xyz="0 0 0" rpy="0 0 0"/>
    <inertial>
      <mass value="2.7"/>
      <inertia ixx="0.012"  ixy="0"  ixz="0" iyy="0.012" iyz="0" izz="0"/>
    </inertial>
    <visual name='visual'>
      <origin xyz="0 0 0" rpy="0 0 0"/>
      <geometry>
        <mesh filename="/opt/rover/meshes/rover/joint4-diff.stl" scale="1 1 1" />
      </geometry>
      <transparency>0</transparency>
      <cast_shadows>1</cast_shadows>
    </visual>
    <gravity>1</gravity>
    <self_collide>0</self_collide>
    <kinematic>0</kinematic>
    <enable_wind>0</enable_wind>
  </link>
  <joint name='differential_joint' type='continuous'>
    <parent link="chassis"/>
    <child link="differential"/>
    <axis xyz="0 1 0"/>
    <origin xyz="-0.230 0 0.128" rpy="1.5707 0 0"/>
  </joint>

  <link name='wheel_1'>
    <origin xyz="0 0 0" rpy="0 0 0"/>
    <inertial>
      <mass value="1"/>
      <inertia ixx="0.013"  ixy="0"  ixz="0" iyy="0.013" iyz="0" izz="0.024"/>
    </inertial>
    <visual name='visual'>
      <origin xyz="0 0 0.034" rpy="0 0 0"/>
      <geometry>
        <mesh filename="/opt/rover/meshes/rover/wheel.stl" scale="1 1 1" />
      </geometry>
      <transparency>0</transparency>
      <cast_shadows>1</cast_shadows>
    </visual>
    <collision name='wheel_1_collision'>
      <origin xyz="0 0 0" rpy="0 0 0"/>
      <laser_retro>0</laser_retro>
      <max_contacts>10</max_contacts>
      <geometry>
        <cylinder length="0.072" radius="0.128" />
      </geometry>
    </collision>
    <gravity>1</gravity>
    <self_collide>0</self_collide>
    <kinematic>0</kinematic>
    <enable_wind>0</enable_wind>
  </link>
  <joint name='wheel_1_joint' type='continuous'>
    <parent link="right_handle"/>
    <child link="wheel_1"/>
    <axis xyz="0 0 1"/>
    <origin xyz="0.264321 -0.213856  0.132" rpy="0 0 0"/>
  </joint>

  <link name='wheel_6'>
    <origin xyz="0 0 0" rpy="0 0 0"/>
    <inertial>
      <mass value="1"/>
      <inertia ixx="0.013"  ixy="0"  ixz="0" iyy="0.013" iyz="0" izz="0.024"/>
    </inertial>
    <visual name='visual'>
      <origin xyz="0 0 0.034" rpy="0 0 0"/>
      <geometry>
        <mesh filename="/opt/rover/meshes/rover/wheel.stl" scale="1 1 1" />
      </geometry>
      <transparency>0</transparency>
      <cast_shadows>1</cast_shadows>
    </visual>
    <collision name='wheel_6_collision'>
      <origin xyz="0 0 0" rpy="0 0 0"/>
      <laser_retro>0</laser_retro>
      <max_contacts>10</max_contacts>
      <geometry>
        <cylinder length="0.072" radius="0.128" />
      </geometry>
    </collision>
    <gravity>1</gravity>
    <self_collide>0</self_collide>
    <kinematic>0</kinematic>
    <enable_wind>0</enable_wind>
  </link>
  <joint name='wheel_6_joint' type='continuous'>
    <parent link="left_handle"/>
    <child link="wheel_6"/>
    <axis xyz="0 0 1"/>
    <origin xyz="0.264321 -0.213856  -0.132" rpy="3.1414 0 0"/>
  </joint>

  <link name='wheel_2'>
    <origin xyz="0 0 0" rpy="0 0 0"/>
    <inertial>
      <mass value="1"/>
      <inertia ixx="0.013"  ixy="0"  ixz="0" iyy="0.013" iyz="0" izz="0.024"/>
    </inertial>
    <visual name='visual'>
      <origin xyz="0 0 0.034" rpy="0 0 0"/>
      <geometry>
        <mesh filename="/opt/rover/meshes/rover/wheel.stl" scale="1 1 1" />
      </geometry>
      <transparency>0</transparency>
      <cast_shadows>1</cast_shadows>
    </visual>
    <collision name='wheel_2_collision'>
      <origin xyz="0 0 0" rpy="0 0 0"/>
      <laser_retro>0</laser_retro>
      <max_contacts>10</max_contacts>
      <geometry>
        <cylinder length="0.072" radius="0.128" />
      </geometry>
    </collision>
    <gravity>1</gravity>
    <self_collide>0</self_collide>
    <kinematic>0</kinematic>
    <enable_wind>0</enable_wind>
  </link>
  <joint name='wheel_2_joint' type='continuous'>
    <parent link="right_boggie"/>
    <child link="wheel_2"/>
    <axis xyz="0 0 1"/>
    <origin xyz="0.167 -0.14  0.138" rpy="0 0 0"/>
  </joint>

  <link name='wheel_5'>
    <origin xyz="0 0 0" rpy="0 0 0"/>
    <inertial>
      <mass value="1"/>
      <inertia ixx="0.013"  ixy="0"  ixz="0" iyy="0.013" iyz="0" izz="0.024"/>
    </inertial>
    <visual name='visual'>
      <origin xyz="0 0 0.034" rpy="0 0 0"/>
      <geometry>
        <mesh filename="/opt/rover/meshes/rover/wheel.stl" scale="1 1 1" />
      </geometry>
      <transparency>0</transparency>
      <cast_shadows>1</cast_shadows>
    </visual>
    <collision name='wheel_5_collision'>
      <origin xyz="0 0 0" rpy="0 0 0"/>
      <laser_retro>0</laser_retro>
      <max_contacts>10</max_contacts>
      <geometry>
        <cylinder length="0.072" radius="0.128" />
      </geometry>
    </collision>
    <gravity>1</gravity>
    <self_collide>0</self_collide>
    <kinematic>0</kinematic>
    <enable_wind>0</enable_wind>
  </link>
  <joint name='wheel_5_joint' type='continuous'>
    <parent link="left_boggie"/>
    <child link="wheel_5"/>
    <axis xyz="0 0 1"/>
    <origin xyz="0.167 -0.14  -0.138" rpy="3.1414 0 0"/>
  </joint>

  <link name='wheel_3'>
    <origin xyz="0 0 0" rpy="0 0 0"/>
    <inertial>
      <mass value="1"/>
      <inertia ixx="0.013"  ixy="0"  ixz="0" iyy="0.013" iyz="0" izz="0.024"/>
    </inertial>
    <visual name='visual'>
      <origin xyz="0 0 0.034" rpy="0 0 0"/>
      <geometry>
        <mesh filename="/opt/rover/meshes/rover/wheel.stl" scale="1 1 1" />
      </geometry>
      <transparency>0</transparency>
      <cast_shadows>1</cast_shadows>
    </visual>
    <collision name='wheel_3_collision'>
      <origin xyz="0 0 0" rpy="0 0 0"/>
      <laser_retro>0</laser_retro>
      <max_contacts>10</max_contacts>
      <geometry>
        <cylinder length="0.072" radius="0.128" />
      </geometry>
    </collision>
    <gravity>1</gravity>
    <self_collide>0</self_collide>
    <kinematic>0</kinematic>
    <enable_wind>0</enable_wind>
  </link>
  <joint name='wheel_3_joint' type='continuous'>
    <parent link="right_boggie"/>
    <child link="wheel_3"/>
    <axis xyz="0 0 1"/>
    <origin xyz="-0.167 -0.14  0.138" rpy="0 0 0"/>
  </joint>

  <link name='wheel_4'>
    <origin xyz="0 0 0" rpy="0 0 0"/>
    <inertial>
      <mass value="1"/>
      <inertia ixx="0.013"  ixy="0"  ixz="0" iyy="0.013" iyz="0" izz="0.024"/>
    </inertial>
    <visual name='visual'>
      <origin xyz="0 0 0.034" rpy="0 0 0"/>
      <geometry>
        <mesh filename="/opt/rover/meshes/rover/wheel.stl" scale="1 1 1" />
      </geometry>
      <transparency>0</transparency>
      <cast_shadows>1</cast_shadows>
    </visual>
    <collision name='wheel_4_collision'>
      <origin xyz="0 0 0" rpy="0 0 0"/>
      <laser_retro>0</laser_retro>
      <max_contacts>10</max_contacts>
      <geometry>
        <cylinder length="0.072" radius="0.128" />
      </geometry>
    </collision>
    <gravity>1</gravity>
    <self_collide>0</self_collide>
    <kinematic>0</kinematic>
    <enable_wind>0</enable_wind>
  </link>
  <joint name='wheel_4_joint' type='continuous'>
    <parent link="left_boggie"/>
    <child link="wheel_4"/>
    <axis xyz="0 0 1"/>
    <origin xyz="-0.167 -0.14  -0.138" rpy="3.1414 0 0"/>
  </joint>

  <gazebo>
    <plugin name="skid_steer_drive_controller" filename="libgazebo_ros_skid_steer_drive.so">
      <alwaysOn>false</alwaysOn>
      <legacyMode>false</legacyMode>
      <updateRate>20</updateRate>
      <commandTopic>cmd_vel</commandTopic>
      <odometryTopic>odom</odometryTopic>
      <odometryFrame>odom</odometryFrame>

      <robotNamespace>/rover</robotNamespace>
      <!-- Very dumb rover steering config-->
      <robotBaseFrame>chassis</robotBaseFrame>
      <leftFrontJoint>wheel_6_joint</leftFrontJoint>
      <rightFrontJoint>wheel_1_joint</rightFrontJoint>
      <leftRearJoint>wheel_4_joint</leftRearJoint>
      <rightRearJoint>wheel_3_joint</rightRearJoint>
      <wheelDiameter>0.256</wheelDiameter>
      <!-- TODO: accurate values for separation, wheelTorque -->
      <wheelSeparation>0.5</wheelSeparation>
      <wheelTorque>20</wheelTorque>
    </plugin>

    <link name='right_diff_rail'>
      <inertial>
        <mass>0.000236124</mass>
        <inertia>
          <ixx>3.68579e-08</ixx>
          <ixy>0</ixy>
          <ixz>0</ixz>
          <iyy>1.28668e-06</iyy>
          <iyz>0</iyz>
          <izz>1.28951e-06</izz>
        </inertia>
        <pose>0 0 0 0 -0 0</pose>
      </inertial>
      <pose>-0.116498 -0.287057 0.138334 0 -0 0</pose>
      <self_collide>0</self_collide>
      <enable_wind>0</enable_wind>
      <kinematic>0</kinematic>
      <visual name='visual'>
        <pose>0 0 0 0 -0 0</pose>
        <geometry>
          <box>
            <size>0.225 0.01 0.01</size>
          </box>
        </geometry>
        <material>
          <lighting>1</lighting>
          <script>
            <uri>file://media/materials/scripts/gazebo.material</uri>
            <name>Gazebo/Grey</name>
          </script>
          <shader type='pixel'/>
          <emissive>0 0 0 1</emissive>
        </material>
        <transparency>0</transparency>
        <cast_shadows>1</cast_shadows>
      </visual>
    </link>
    <link name='left_diff_rail'>
      <inertial>
        <mass>0.000236124</mass>
        <inertia>
          <ixx>3.68579e-08</ixx>
          <ixy>0</ixy>
          <ixz>0</ixz>
          <iyy>1.28668e-06</iyy>
          <iyz>0</iyz>
          <izz>1.28951e-06</izz>
        </inertia>
        <pose>0 0 0 0 -0 0</pose>
      </inertial>
      <pose>-0.108281 0.282192 0.138334 0 -0 0</pose>
      <self_collide>0</self_collide>
      <enable_wind>0</enable_wind>
      <kinematic>0</kinematic>
      <visual name='visual'>
        <pose>0 0 0 0 -0 0</pose>
        <geometry>
          <box>
            <size>0.225 0.01 0.01</size>
          </box>
        </geometry>
        <material>
          <lighting>1</lighting>
          <script>
            <uri>file://media/materials/scripts/gazebo.material</uri>
            <name>Gazebo/Grey</name>
          </script>
          <shader type='pixel'/>
          <emissive>0 0 0 1</emissive>
        </material>
        <transparency>0</transparency>
        <cast_shadows>1</cast_shadows>
      </visual>
    </link>
    <joint name='right_diff_rail_to_diff' type='fixed'>  # TODO: or revolute/revolute2/ball ?
      <parent>right_diff_rail</parent>
      <child>differential</child>
      <pose>0 0 0.25 0 -0 0</pose>
      <axis>
        <xyz>0 0 1</xyz>
        <limit>
          <lower>-1e+16</lower>
          <upper>1e+16</upper>
          <effort>-1</effort>
          <velocity>-1</velocity>
        </limit>
        <dynamics>
          <spring_reference>0</spring_reference>
          <spring_stiffness>0</spring_stiffness>
          <damping>0</damping>
          <friction>0</friction>
        </dynamics>
      </axis>
      <physics>
        <ode>
          <limit>
            <cfm>0</cfm>
            <erp>0.2</erp>
          </limit>
          <suspension>
            <cfm>0</cfm>
            <erp>0.2</erp>
          </suspension>
        </ode>
      </physics>
    </joint>
    <joint name='right_diff_rail_to_handle' type='revolute'>
      <parent>right_diff_rail</parent>
      <child>right_handle</child>
      <pose>0 0.15 0 0 -0 0</pose>
      <axis>
        <xyz>0 0 1</xyz>
        <limit>
          <lower>-1e+16</lower>
          <upper>1e+16</upper>
          <effort>-1</effort>
          <velocity>-1</velocity>
        </limit>
        <dynamics>
          <spring_reference>0</spring_reference>
          <spring_stiffness>0</spring_stiffness>
          <damping>0</damping>
          <friction>0</friction>
        </dynamics>
      </axis>
      <physics>
        <ode>
          <limit>
            <cfm>0</cfm>
            <erp>0.2</erp>
          </limit>
          <suspension>
            <cfm>0</cfm>
            <erp>0.2</erp>
          </suspension>
        </ode>
      </physics>
    </joint>
    <joint name='left_diff_rail_to_handle' type='revolute'>
      <parent>left_diff_rail</parent>
      <child>left_handle</child>
      <pose>0 0.15 0 0 -0 0</pose>
      <axis>
        <xyz>0 0 1</xyz>
        <limit>
          <lower>-1e+16</lower>
          <upper>1e+16</upper>
          <effort>-1</effort>
          <velocity>-1</velocity>
        </limit>
        <dynamics>
          <spring_reference>0</spring_reference>
          <spring_stiffness>0</spring_stiffness>
          <damping>0</damping>
          <friction>0</friction>
        </dynamics>
      </axis>
      <physics>
        <ode>
          <limit>
            <cfm>0</cfm>
            <erp>0.2</erp>
          </limit>
          <suspension>
            <cfm>0</cfm>
            <erp>0.2</erp>
          </suspension>
        </ode>
      </physics>
    </joint>
    <joint name='left_diff_rail_to_diff' type='fixed'> # TODO: or revolute/revolute2/ball ?
      <parent>left_diff_rail</parent>
      <child>differential</child>
      <pose>0 0 -0.25 0 -0 0</pose>
      <axis>
        <xyz>0 0 1</xyz>
        <limit>
          <lower>-1e+16</lower>
          <upper>1e+16</upper>
          <effort>-1</effort>
          <velocity>-1</velocity>
        </limit>
        <dynamics>
          <spring_reference>0</spring_reference>
          <spring_stiffness>0</spring_stiffness>
          <damping>0</damping>
          <friction>0</friction>
        </dynamics>
      </axis>
      <physics>
        <ode>
          <limit>
            <cfm>0</cfm>
            <erp>0.2</erp>
          </limit>
          <suspension>
            <cfm>0</cfm>
            <erp>0.2</erp>
          </suspension>
        </ode>
      </physics>
    </joint>
  </gazebo>
</robot>
